Workbook

Sheet Orçamento FieldOps
A1: Orçamento do Projeto FieldOps — Plataforma de Inspeção em Campo
A2: Gestão de Projetos — SENAI | Elaborado com base no Documento de Visão e Objetivos do FieldOps
A4: Qt | B4: Unid | C4: Descrição | D4: Categoria | E4: Responsável | F4: Valor Unitário | G4: Total | H4: Origem/Observação
A5: 1. Recursos Humanos — Equipe de Desenvolvimento
A6: 1 | B6: mês | C6: Desenvolvedor(a) Mobile (Expo/React Native) | D6: Recursos Humanos | E6: Estudante — Squad Mobile | F6: 2200 | G6: =A6*F6 -> 2200 | H6: Estimativa de bolsa/hora-aula equivalente
A7: 1 | B7: mês | C7: Desenvolvedor(a) Backend (Java/Spring Boot) | D7: Recursos Humanos | E7: Estudante — Squad Backend | F7: 2200 | G7: =A7*F7 -> 2200 | H7: Estimativa de bolsa/hora-aula equivalente
A8: 1 | B8: mês | C8: Desenvolvedor(a) Web Administrativo (Angular/React) | D8: Recursos Humanos | E8: Estudante — Squad Web | F8: 2200 | G8: =A8*F8 -> 2200 | H8: Estimativa de bolsa/hora-aula equivalente
A9: 1 | B9: mês | C9: Analista de Qualidade / Testes (QA) | D9: Recursos Humanos | E9: Estudante — Squad QA | F9: 1800 | G9: =A9*F9 -> 1800 | H9: Testes funcionais e de integração
A10: 1 | B10: mês | C10: Gerente de Projeto | D10: Recursos Humanos | E10: Estudante — Coordenação | F10: 2000 | G10: =A10*F10 -> 2000 | H10: Planejamento, acompanhamento e riscos
A11: 1 | B11: mês | C11: Designer UX/UI | D11: Recursos Humanos | E11: Estudante — Squad Web/Mobile | F11: 1600 | G11: =A11*F11 -> 1600 | H11: Protótipos e padronização visual
A12: 1 | B12: mês | C12: Professor Orientador (horas de consultoria) | D12: Recursos Humanos | E12: Prof. Me. Deivison S. Takatu | F12: 900 | G12: =A12*F12 -> 900 | H12: 20h de orientação no mês
A13: 2. Infraestrutura e Nuvem
A14: 1 | B14: mês | C14: Servidor de aplicação (API REST) em nuvem | D14: Infraestrutura | E14: DevOps/Infra | F14: 120 | G14: =A14*F14 -> 120 | H14: Ex.: instância cloud básica
A15: 1 | B15: mês | C15: Banco de dados PostgreSQL gerenciado | D15: Infraestrutura | E15: DevOps/Infra | F15: 90 | G15: =A15*F15 -> 90 | H15: Ambiente de produção
A16: 1 | B16: mês | C16: Armazenamento de objetos para evidências (fotos) | D16: Infraestrutura | E16: DevOps/Infra | F16: 60 | G16: =A16*F16 -> 60 | H16: Compatível com S3
A17: 1 | B17: un | C17: Domínio (.com.br) — 1 ano | D17: Infraestrutura | E17: DevOps/Infra | F17: 45 | G17: =A17*F17 -> 45 | H17: Registro.br
A18: 1 | B18: un | C18: Certificado SSL | D18: Infraestrutura | E18: DevOps/Infra | F18: 0 | G18: =A18*F18 -> 0 | H18: Let's Encrypt — gratuito
A19: 3 | B19: mês | C19: Ambiente de homologação/testes (dev+staging) | D19: Infraestrutura | E19: DevOps/Infra | F19: 70 | G19: =A19*F19 -> 210 | H19: 3 meses de projeto
A20: 1 | B20: mês | C20: Serviço de CI/CD (build e deploy automatizado) | D20: Infraestrutura | E20: DevOps/Infra | F20: 0 | G20: =A20*F20 -> 0 | H20: GitHub Actions — plano gratuito
A21: 3. Software e Licenças
A22: 3 | B22: licença | C22: IDE / Android Studio | D22: Software | E22: Squad Mobile | F22: 0 | G22: =A22*F22 -> 0 | H22: Gratuito
A23: 1 | B23: licença | C23: Postman Team (colaboração de API) | D23: Software | E23: Squad Backend | F23: 0 | G23: =A23*F23 -> 0 | H23: Plano gratuito
A24: 1 | B24: licença | C24: Figma (design colaborativo) | D24: Software | E24: Design UX/UI | F24: 0 | G24: =A24*F24 -> 0 | H24: Plano gratuito/educacional
A25: 1 | B25: licença | C25: Conta Google Play Console (publicação Android) | D25: Software | E25: Gerente de Projeto | F25: 125 | G25: =A25*F25 -> 125 | H25: Taxa única de desenvolvedor
A26: 1 | B26: licença | C26: Repositório privado GitHub (organização) | D26: Software | E26: Gerente de Projeto | F26: 0 | G26: =A26*F26 -> 0 | H26: Plano gratuito/educacional
A27: 1 | B27: licença | C27: Ferramenta de gestão ágil (quadro Kanban) | D27: Software | E27: Gerente de Projeto | F27: 0 | G27: =A27*F27 -> 0 | H27: Trello/GitHub Projects — gratuito
A28: 4. Equipamentos e Dispositivos
A29: 2 | B29: un | C29: Smartphone Android para testes de campo | D29: Equipamento | E29: Squad QA | F29: 900 | G29: =A29*F29 -> 1800 | H29: Validação obrigatória em Android
A30: 1 | B30: un | C30: Leitor/gerador de QR Code para testes de equipamento | D30: Equipamento | E30: Squad Mobile | F30: 35 | G30: =A30*F30 -> 35 | H30: Etiquetas de teste
A31: 1 | B31: un | C31: Notebook reserva para testes de homologação | D31: Equipamento | E31: Squad QA | F31: 2500 | G31: =A31*F31 -> 2500 | H31: Já disponível — custo de referência
A32: 1 | B32: un | C32: Roteador móvel (simulação de campo sem internet) | D32: Equipamento | E32: Squad Mobile | F32: 180 | G32: =A32*F32 -> 180 | H32: Testes de modo offline
A33: 5. Documentação e Testes
A34: 1 | B34: un | C34: Elaboração de documento de requisitos e casos de uso | D34: Documentação | E34: Gerente de Projeto | F34: 0 | G34: =A34*F34 -> 0 | H34: Horas já contabilizadas em RH
A35: 1 | B35: un | C35: Documentação da API (OpenAPI/Swagger) | D35: Documentação | E35: Squad Backend | F35: 0 | G35: =A35*F35 -> 0 | H35: Ferramenta gratuita integrada ao Spring Boot
A36: 40 | B36: hora | C36: Execução de testes funcionais e de regressão | D36: Documentação | E36: Squad QA | F36: 25 | G36: =A36*F36 -> 1000 | H36: Ciclo de testes do MVP
A37: 1 | B37: un | C37: Relatório de auditoria e rastreabilidade (LGPD) | D37: Documentação | E37: Gerente de Projeto | F37: 150 | G37: =A37*F37 -> 150 | H37: Consultoria pontual
A38: 6. Comunicação e Deslocamento
A39: 3 | B39: visita | C39: Visita técnica a cliente piloto para levantamento | D39: Serviços | E39: Gerente de Projeto | F39: 60 | G39: =A39*F39 -> 180 | H39: Transporte + alimentação
A40: 1 | B40: un | C40: Material de divulgação/apresentação do MVP | D40: Serviços | E40: Design UX/UI | F40: 80 | G40: =A40*F40 -> 80 | H40: Impressão e material gráfico
A41: 1 | B41: mês | C41: Ferramenta de comunicação da equipe (Slack/Teams) | D41: Serviços | E41: Gerente de Projeto | F41: 0 | G41: =A41*F41 -> 0 | H41: Plano gratuito
...

Sheet Resumo por Categoria
A1: Resumo do Orçamento por Categoria — Projeto FieldOps
A3: Categoria | B3: Total (R$) | C3: % do Total
A4: Contingência | B4: =SUMIF('Orçamento FieldOps'!D5:D43,A4,'Orçamento FieldOps'!G5:G43) -> 973.75 | C4: =B4/$B$11 -> 0.047619048
A5: Documentação | B5: =SUMIF('Orçamento FieldOps'!D5:D43,A5,'Orçamento FieldOps'!G5:G43) -> 1150 | C5: =B5/$B$11 -> 0.056238156
A6: Equipamento | B6: =SUMIF('Orçamento FieldOps'!D5:D43,A6,'Orçamento FieldOps'!G5:G43) -> 4515 | C6: =B6/$B$11 -> 0.22079589
A7: Infraestrutura | B7: =SUMIF('Orçamento FieldOps'!D5:D43,A7,'Orçamento FieldOps'!G5:G43) -> 525 | C7: =B7/$B$11 -> 0.025673941
A8: Recursos Humanos | B8: =SUMIF('Orçamento FieldOps'!D5:D43,A8,'Orçamento FieldOps'!G5:G43) -> 12900 | C8: =B8/$B$11 -> 0.63084541
A9: Serviços | B9: =SUMIF('Orçamento FieldOps'!D5:D43,A9,'Orçamento FieldOps'!G5:G43) -> 260 | C9: =B9/$B$11 -> 0.012714714
A10: Software | B10: =SUMIF('Orçamento FieldOps'!D5:D43,A10,'Orçamento FieldOps'!G5:G43) -> 125 | C10: =B10/$B$11 -> 0.0061128431
A11: TOTAL GERAL | B11: =SUM(B4:B10) -> 20448.75
